Workbook

Sheet Thông tin doanh nghiệp
A1: Vai trò | B1: Tên công ty | C1: Mã số thuế | D1: Địa chỉ
A2: Doanh nghiệp thực hành | B2: Công ty cổ phần FAAbulous | C2: 0123456789 | D2: Phường Láng, Hà Nội
A3: Nhà cung cấp (người bán)
A4: Thiết bị văn phòng | B4: Công ty cổ phần Hòa Bình | C4: 0000000001 | D4: Phường Kim Liên, Hà Nôi
A5: Máy tính HP | B5: Công ty cổ phần Thế giới số | C5: 0000000002 | D5: Phường Đống Đa, Hà Nội
A6: Máy tính Dell | B6: Công ty cổ phần Thiết bị di động | C6: 0000000003 | D6: Phường Hà Đông, Hà Nội
A7: Máy tính Macbook | B7: Công ty TNHH Hàng điện tử | C7: 0000000004 | D7: Xã Sóc Sơn, Hà Nội
A9: Khách hàng
B10: Công ty TNHH Phúc Sơn | C10: 0000000005 | D10: Phường Phú Diễn, Hà Nội
B11: Công ty cổ phần An Bình | C11: 0000000006 | D11: Phường Ô Chợ Dừa, Hà Nội
B12: Công ty TNHH Xuân Phương | C12: 0000000007 | D12: Xã Xuân Trường, Nam Định

Sheet Kịch bản
A1: I | B1: THÔNG TIN DOANH NGHIỆP
A2: 1 | B2: Tên doanh nghiệp: | C2: Công ty cổ phần FAAbulous
A3: 2 | B3: Mặt hàng kinh doanh: | C3: Thiết bị điện tử
A4: 3 | B4: Kỳ kế toán: | C4: Tháng 1 năm 20X6
A5: 4 | B5: Phương pháp kế toán sử dụng:
B6: Phương pháp tính thuế GTGT: | C6: Khấu trừ
B7: Phương pháp khấu hao: | C7: Đường thẳng
B8: Phương pháp tính giá hàng xuất kho: | C8: Bình quân gia quyền
D10: Task 1: Thực hành lập chứng từ | F10: Task 2: Thực hành nhập liệu và định khoản
A11: II | B11: CÁC NGHIỆP VỤ PHÁT SINH TRONG THÁNG | D11: Sinh viên | E11: Ghi chú | F11: Sinh viên
A12: 1 | B12: Ngày 10/01/20X6, các chủ sở hữu góp vốn kinh doanh 10 tỷ bằng chuyển khoản. | F12: Nhập liệu trên phân hệ Tiền gửi ngân hàng
A13: 2 | B13: Ngày 15/01/20X6, vay ngân hàng 2 tỷ, thời hạn 1 năm, lãi suất 12%/năm, thanh toán lãi hàng tháng bằng chuyển khoản, trả gốc khi đáo hạn. | F13: Nhập liệu trên phân hệ Tiền gửi ngân hàng
A14: 3 | B14: Ngày 15/01/20X6 rút tiền gửi ngân hàng về nhập quỹ tiền mặt 300 triệu | F14: Nhập liệu trên phân hệ Tiền gửi ngân hàng
A15: 4 | B15: Ngày 16/01/20X6, mua thiết bị văn phòng trị giá 100 triệu, chưa bao gồm thuế GTGT 10% được khấu trừ, chi phí lắp đặt các thiết bị trên là 2 triệu, đã thanh toán bằng chuyển khoản. Tài sản dự kiến sử dụng 10 năm | F15: Nhập liệu trên phân hệ Mua hàng
A16: 5 | B16: Ngày 16/01/20X6, mua 10 chiếc máy tính, đã nhập kho, đã thanh toán chuyển khoản. | D16: Thực hành lập hóa đơn, chọn 1 trong 3 mặt hàng: 1. Máy tính HP, giá mua 10 triệu/chiếc 2. Máy tính Dell, giá mua 12 triệu/chiếc 3. Máy tính Macbook, giá mua 20 triệu/chiếc Giá máy tính chưa bao gồm VAT 10% | E16: Xem sheet Thông tin doanh nghiệp | F16: Nhập liệu trên phân hệ Mua hàng
A17: 6 | B17: Ngày 16/01/20X6, thanh toán tiền thuê nhà quý 1 (tháng 1,2,3) 30 triệu bằng chuyển khoản. | F17: Nhập liệu trên phân hệ Tiền gửi ngân hàng
A18: 7 | B18: Ngày 20/01/20X6, mua 20 chiếc máy tính, đã nhập kho, chưa thanh toán. | E18: Cùng loại với máy tính ở nghiệp vụ 5, chọn 1 trong 3 mặt hàng: 1. Máy tính HP, giá mua 12 triệu/chiếc 2. Máy tính Dell, giá mua 14 triệu/chiếc 3. Máy tính Macbook, giá mua 22 triệu/chiếc Giá máy tính chưa bao gồm VAT 10% | F18: Nhập liệu trên phân hệ Mua hàng
A19: 8 | B19: Ngày 18/01/20X6, bán 15 chiếc máy tính cho công ty Phúc Sơn, đã giao hàng cho khách, khách hàng đã thanh toán chuyển khoản. | D19: Thực hành lập hóa đơn và giấy báo Có, chọn 1 trong 3 mặt hàng: 1. Máy tính HP, giá bán 20 triệu/chiếc 2. Máy tính Dell, giá bán 24 triệu/chiếc 3. Máy tính Macbook, giá bán 40 triệu/chiếc Giá máy tính chưa bao gồm VAT 10% | E19: Cùng loại với máy tính ở nghiệp vụ 5 và 7 | F19: Nhập liệu trên phân hệ Bán hàng
A20: 9 | B20: Ngày 20/01/20X6, bán 12 chiếc máy tính cho công ty An Bình, đã giao hàng cho khách, khách hàng chưa thanh toán | E20: Cùng loại với máy tính ở nghiệp vụ 8. 1. Máy tính HP, giá bán 24 triệu/chiếc 2. Máy tính Dell, giá bán 28 triệu/chiếc 3. Máy tính Macbook, giá bán 44 triệu/chiếc Giá máy tính chưa bao gồm VAT 10% | F20: Nhập liệu trên phân hệ Bán hàng
A21: 10 | B21: Ngày 22/01/20X6, mua 10 chiếc máy tính, đã nhập kho, đã thanh toán chuyển khoản. | E21: Cùng loại với máy tính ở nghiệp vụ 5, chọn 1 trong 3 mặt hàng: 1. Máy tính HP, giá mua 12 triệu/chiếc 2. Máy tính Dell, giá mua 14 triệu/chiếc 3. Máy tính Macbook, giá mua 22 triệu/chiếc Giá máy tính chưa bao gồm VAT 10% | F21: Nhập liệu trên phân hệ Mua hàng
A22: 11 | B22: Ngày 25/01/20X6, bán 5 chiếc máy tính cho công ty Xuân Phương, đã giao hàng cho khách, khách hàng đã thanh toán chuyển khoản. | E22: Cùng loại với máy tính ở nghiệp vụ 8. 1. Máy tính HP, giá bán 24 triệu/chiếc 2. Máy tính Dell, giá bán 28 triệu/chiếc 3. Máy tính Macbook, giá bán 44 triệu/chiếc Giá máy tính chưa bao gồm VAT 10% | F22: Nhập liệu trên phân hệ Bán hàng
A23: 12 | B23: Ngày 31/01/20X6, tiền lương trong tháng của bộ phận bán hàng là 50 triệu, bộ phận quản lý là 20 triệu chưa thanh toán. Các khoản bảo hiểm phải đóng cho nhân viên bán hàng là 10 triệu, nhân viên quản lý doanh nghiệp là 4 triệu, phần trích từ lương nhân viên là 7 triệu chưa nộp. | F23: Nhập liệu trên phân hệ Phiếu Kế toán
A24: 13 | B24: Ngày 31/01/20X6, trích khấu hao của tài sản cố định dùng ở bộ phận quản lý | F24: Nhập liệu trên phân hệ Phiếu Kế toán
A25: 14 | B25: Ngày 31/01/20X6, phân bổ chi phí thuê văn phòng trong tháng là 10 triệu. | F25: Nhập liệu trên phân hệ Phiếu Kế toán
A26: 15 | B26: Ngày 31/01/20X6, ghi nhận chi phí lãi vay chưa thanh toán trong kỳ là 10 triệu. | F26: Nhập liệu trên phân hệ Phiếu Kế toán
B27: Hết

Sheet Mẫu hóa đơn_Giấy báo có

Sheet Mẫu các phân hệ kế toán

Sheet Sổ Nhật ký chung
B1: CÔNG TY TNHH FAAbulous
B2: SỔ NHẬT KÝ CHUNG
B3: Tháng 1 năm 20X6
B4: ĐVT: đồng
A5: STT | B5: NGHIỆP VỤ | C5: TK ĐỐI ỨNG | D5: NỢ | E5: CÓ
A6: 1 | B6: =VLOOKUP(A6,'Kịch bản'!$A$12:$C$26,2,FALSE) -> Ngày 10/01/20X6, các chủ sở hữu góp vốn kinh doanh 10 tỷ bằng chuyển khoản. | C6: 112 | D6: 5000000000
A7: 1 | B7: =VLOOKUP(A7,'Kịch bản'!$A$12:$C$26,2,FALSE) -> Ngày 10/01/20X6, các chủ sở hữu góp vốn kinh doanh 10 tỷ bằng chuyển khoản. | C7: 411 | E7: =D6 -> 5000000000
A8: 2 | B8: =VLOOKUP(A8,'Kịch bản'!$A$12:$C$26,2,FALSE) -> Ngày 15/01/20X6, vay ngân hàng 2 tỷ, thời hạn 1 năm, lãi suất 12%/năm, thanh toán lãi hàng tháng bằng chuyển khoản, trả gốc khi đáo hạn. | C8: 112 | D8: 2000000000
A9: 2 | B9: =VLOOKUP(A9,'Kịch bản'!$A$12:$C$26,2,FALSE) -> Ngày 15/01/20X6, vay ngân hàng 2 tỷ, thời hạn 1 năm, lãi suất 12%/năm, thanh toán lãi hàng tháng bằng chuyển khoản, trả gốc khi đáo hạn. | C9: 341 | E9: =D8 -> 2000000000
A10: 3 | B10: =VLOOKUP(A10,'Kịch bản'!$A$12:$C$26,2,FALSE) -> Ngày 15/01/20X6 rút tiền gửi ngân hàng về nhập quỹ tiền mặt 300 triệu | C10: 111 | D10: 300000000
C11: 112 | E11: =D10 -> 300000000
A12: 4 | B12: =VLOOKUP(A12,'Kịch bản'!$A$12:$C$26,2,FALSE) -> Ngày 16/01/20X6, mua thiết bị văn phòng trị giá 100 triệu, chưa bao gồm thuế GTGT 10% được khấu trừ, chi phí lắp đặt các thiết bị trên là 2 triệu, đã thanh toán bằng chuyển khoản. Tài sản dự kiến sử dụng 10 năm | C12: 211 | D12: 102000000
C13: 133 | D13: 10000000
C14: 112 | E14: 112000000
A16: 5 | B16: =VLOOKUP(A16,'Kịch bản'!$A$12:$C$26,2,FALSE) -> Ngày 16/01/20X6, mua 10 chiếc máy tính, đã nhập kho, đã thanh toán chuyển khoản. | C16: 156 | D16: 100000000 | F16: Máy HP
A17: 5 | C17: 133 | D17: 10000000
C18: 112 | E18: 110000000
A19: 6 | B19: =VLOOKUP(A19,'Kịch bản'!$A$12:$C$26,2,FALSE) -> Ngày 16/01/20X6, thanh toán tiền thuê nhà quý 1 (tháng 1,2,3) 30 triệu bằng chuyển khoản. | C19: 242 | D19: 30000000
C20: 112 | E20: =D19 -> 30000000
A21: 7 | B21: =VLOOKUP(A21,'Kịch bản'!$A$12:$C$26,2,FALSE) -> Ngày 20/01/20X6, mua 20 chiếc máy tính, đã nhập kho, chưa thanh toán. | C21: 156 | D21: 240000000
C22: 133 | D22: =10%*D21 -> 24000000
C23: 331 | E23: =D22+D21 -> 264000000
A24: 8 | B24: =VLOOKUP(A24,'Kịch bản'!$A$12:$C$26,2,FALSE) -> Ngày 18/01/20X6, bán 15 chiếc máy tính cho công ty Phúc Sơn, đã giao hàng cho khách, khách hàng đã thanh toán chuyển khoản. | C24: 112 | D24: =15*20000000*1.1 -> 330000000
C25: 511 | E25: 300000000
C26: 3331 | E26: 30000000
C27: 632 | D27: =F28*15 -> 170000000 | F27: Giá bình quân
C28: 156 | E28: =D27 -> 170000000 | F28: =(D16+D21)/30 -> 11333333
A29: 9 | B29: =VLOOKUP(A29,'Kịch bản'!$A$12:$C$26,2,FALSE) -> Ngày 20/01/20X6, bán 12 chiếc máy tính cho công ty An Bình, đã giao hàng cho khách, khách hàng chưa thanh toán | C29: 131 | D29: =12*24000000*1.1 -> 316800000
C30: 511 | E30: =12*24000000 -> 288000000
C31: 3331 | E31: =E30*10% -> 28800000
C32: 632 | D32: =12*F28 -> 136000000
C33: 156 | E33: =D32 -> 136000000
A34: 10 | B34: =VLOOKUP(A34,'Kịch bản'!$A$12:$C$26,2,FALSE) -> Ngày 22/01/20X6, mua 10 chiếc máy tính, đã nhập kho, đã thanh toán chuyển khoản. | C34: 156 | D34: =10*12000000 -> 120000000
C35: 133 | D35: =D34*10% -> 12000000
C36: 112 | E36: =D34+D35 -> 132000000
A37: 11 | B37: =VLOOKUP(A37,'Kịch bản'!$A$12:$C$26,2,FALSE) -> Ngày 25/01/20X6, bán 5 chiếc máy tính cho công ty Xuân Phương, đã giao hàng cho khách, khách hàng đã thanh toán chuyển khoản. | C37: 112 | D37: =5*24000000*1.1 -> 1.32e+08
C38: 511 | E38: =5*24000000 -> 120000000
C39: 3331 | E39: =E38*10% -> 12000000
C40: 632 | D40: =F41*5 -> 59230769 | F40: Giá bình quân
C41: 156 | E41: =D40 -> 59230769 | F41: =(F28*3+D34)/13 -> 11846154
...

Sheet Bang can doi so phat sinh
C1: CÔNG TY CỔ PHẦN FAABULOUS
C2: BẢNG CÂN ĐỐI SỐ PHÁT SINH
C3: Tháng 1 năm 20X6
C4: ĐVT: đồng | D4: ĐVT: triệu đồng
A5: STT | B5: TÀI KHOẢN | C5: SỐ HIỆU | D5: SỐ ĐẦU KỲ | F5: SỐ PHÁT SINH | H5: SỐ CUỐI KỲ
D6: NỢ | E6: CÓ | F6: NỢ | G6: CÓ | H6: NỢ | I6: CÓ
A7: 1 | B7: Tiền mặt | C7: 111 | D7: 0 | F7: =SUMIF('Sổ Nhật ký chung'!$C$6:$C$65,'Bang can doi so phat sinh'!C7,'Sổ Nhật ký chung'!$D$6:$D$65) -> 300000000 | G7: =SUMIF('Sổ Nhật ký chung'!$C$6:$C$65,'Bang can doi so phat sinh'!C7,'Sổ Nhật ký chung'!$E$6:$E$65) -> 0 | H7: =D7+F7-G7 -> 300000000
A8: 2 | B8: Tiền gửi ngân hàng | C8: 112 | D8: 0 | F8: =SUMIF('Sổ Nhật ký chung'!$C$6:$C$65,'Bang can doi so phat sinh'!C8,'Sổ Nhật ký chung'!$D$6:$D$65) -> 7462000000 | G8: =SUMIF('Sổ Nhật ký chung'!$C$6:$C$65,'Bang can doi so phat sinh'!C8,'Sổ Nhật ký chung'!$E$6:$E$65) -> 694000000 | H8: =D8+F8-G8 -> 6768000000
A9: 3 | B9: Phải thu khách hàng | C9: 131 | D9: 0 | F9: =SUMIF('Sổ Nhật ký chung'!$C$6:$C$65,'Bang can doi so phat sinh'!C9,'Sổ Nhật ký chung'!$D$6:$D$65) -> 316800000 | G9: =SUMIF('Sổ Nhật ký chung'!$C$6:$C$65,'Bang can doi so phat sinh'!C9,'Sổ Nhật ký chung'!$E$6:$E$65) -> 0 | H9: =D9+F9-G9 -> 316800000
A10: 4 | B10: Thuế GTGT được khấu trừ | C10: 133 | D10: 0 | F10: =SUMIF('Sổ Nhật ký chung'!$C$6:$C$65,'Bang can doi so phat sinh'!C10,'Sổ Nhật ký chung'!$D$6:$D$65) -> 56000000 | G10: =SUMIF('Sổ Nhật ký chung'!$C$6:$C$65,'Bang can doi so phat sinh'!C10,'Sổ Nhật ký chung'!$E$6:$E$65) -> 56000000 | H10: =D10+F10-G10 -> 0
A11: 5 | B11: Hàng hóa | C11: 156 | D11: 0 | F11: =SUMIF('Sổ Nhật ký chung'!$C$6:$C$65,'Bang can doi so phat sinh'!C11,'Sổ Nhật ký chung'!$D$6:$D$65) -> 460000000 | G11: =SUMIF('Sổ Nhật ký chung'!$C$6:$C$65,'Bang can doi so phat sinh'!C11,'Sổ Nhật ký chung'!$E$6:$E$65) -> 3.6523077e+08 | H11: =D11+F11-G11 -> 94769231
A12: 6 | B12: TSCĐ hữu hình | C12: 211 | D12: 0 | F12: =SUMIF('Sổ Nhật ký chung'!$C$6:$C$65,'Bang can doi so phat sinh'!C12,'Sổ Nhật ký chung'!$D$6:$D$65) -> 102000000 | G12: =SUMIF('Sổ Nhật ký chung'!$C$6:$C$65,'Bang can doi so phat sinh'!C12,'Sổ Nhật ký chung'!$E$6:$E$65) -> 0 | H12: =D12+F12-G12 -> 102000000
A13: 7 | B13: Hao mòn TSCĐ | C13: 214 | E13: 0 | F13: =SUMIF('Sổ Nhật ký chung'!$C$6:$C$65,'Bang can doi so phat sinh'!C13,'Sổ Nhật ký chung'!$D$6:$D$65) -> 0 | G13: =SUMIF('Sổ Nhật ký chung'!$C$6:$C$65,'Bang can doi so phat sinh'!C13,'Sổ Nhật ký chung'!$E$6:$E$65) -> 425000 | I13: =E13-F13+G13 -> 425000
A14: 8 | B14: Chi phí chờ phân bổ | C14: 242 | D14: 0 | F14: =SUMIF('Sổ Nhật ký chung'!$C$6:$C$65,'Bang can doi so phat sinh'!C14,'Sổ Nhật ký chung'!$D$6:$D$65) -> 30000000 | G14: =SUMIF('Sổ Nhật ký chung'!$C$6:$C$65,'Bang can doi so phat sinh'!C14,'Sổ Nhật ký chung'!$E$6:$E$65) -> 10000000 | H14: =D14+F14-G14 -> 20000000
A15: 9 | B15: Phải trả người bán | C15: 331 | E15: 0 | F15: =SUMIF('Sổ Nhật ký chung'!$C$6:$C$65,'Bang can doi so phat sinh'!C15,'Sổ Nhật ký chung'!$D$6:$D$65) -> 0 | G15: =SUMIF('Sổ Nhật ký chung'!$C$6:$C$65,'Bang can doi so phat sinh'!C15,'Sổ Nhật ký chung'!$E$6:$E$65) -> 264000000 | I15: =E15+G15-F15 -> 264000000
A16: 10 | B16: Thuế GTGT phải nộp | C16: 3331 | E16: 0 | F16: =SUMIF('Sổ Nhật ký chung'!$C$6:$C$65,'Bang can doi so phat sinh'!C16,'Sổ Nhật ký chung'!$D$6:$D$65) -> 56000000 | G16: =SUMIF('Sổ Nhật ký chung'!$C$6:$C$65,'Bang can doi so phat sinh'!C16,'Sổ Nhật ký chung'!$E$6:$E$65) -> 70800000 | I16: =E16+G16-F16 -> 14800000
A17: 11 | B17: Phải trả công nhân viên | C17: 334 | E17: 0 | F17: =SUMIF('Sổ Nhật ký chung'!$C$6:$C$65,'Bang can doi so phat sinh'!C17,'Sổ Nhật ký chung'!$D$6:$D$65) -> 7000000 | G17: =SUMIF('Sổ Nhật ký chung'!$C$6:$C$65,'Bang can doi so phat sinh'!C17,'Sổ Nhật ký chung'!$E$6:$E$65) -> 70000000 | I17: =E17+G17-F17 -> 63000000
A18: 12 | B18: Các khoản phải trả khác | C18: 338 | E18: 0 | F18: =SUMIF('Sổ Nhật ký chung'!$C$6:$C$65,'Bang can doi so phat sinh'!C18,'Sổ Nhật ký chung'!$D$6:$D$65) -> 0 | G18: =SUMIF('Sổ Nhật ký chung'!$C$6:$C$65,'Bang can doi so phat sinh'!C18,'Sổ Nhật ký chung'!$E$6:$E$65) -> 21000000 | I18: =E18+G18-F18 -> 21000000
A19: 13 | B19: Vay | C19: 341 | E19: 0 | F19: =SUMIF('Sổ Nhật ký chung'!$C$6:$C$65,'Bang can doi so phat sinh'!C19,'Sổ Nhật ký chung'!$D$6:$D$65) -> 0 | G19: =SUMIF('Sổ Nhật ký chung'!$C$6:$C$65,'Bang can doi so phat sinh'!C19,'Sổ Nhật ký chung'!$E$6:$E$65) -> 2000000000 | I19: =E19+G19-F19 -> 2000000000
A20: 14 | B20: vốn đầu tư của chủ sở hữu | C20: 411 | E20: 0 | F20: =SUMIF('Sổ Nhật ký chung'!$C$6:$C$65,'Bang can doi so phat sinh'!C20,'Sổ Nhật ký chung'!$D$6:$D$65) -> 0 | G20: =SUMIF('Sổ Nhật ký chung'!$C$6:$C$65,'Bang can doi so phat sinh'!C20,'Sổ Nhật ký chung'!$E$6:$E$65) -> 5000000000 | I20: =E20+G20-F20 -> 5000000000
A21: 15 | B21: Lợi nhuận chưa phân phối | C21: 421 | E21: 0 | F21: =SUMIF('Sổ Nhật ký chung'!$C$6:$C$65,'Bang can doi so phat sinh'!C21,'Sổ Nhật ký chung'!$D$6:$D$65) -> 0 | G21: =SUMIF('Sổ Nhật ký chung'!$C$6:$C$65,'Bang can doi so phat sinh'!C21,'Sổ Nhật ký chung'!$E$6:$E$65) -> 2.3834423e+08 | I21: =E21+G21-F21 -> 2.3834423e+08
A22: 16 | B22: Doanh thu bán hàng và cung cấp dịch vụ | C22: 511 | D22: 0 | E22: 0 | F22: =SUMIF('Sổ Nhật ký chung'!$C$6:$C$65,'Bang can doi so phat sinh'!C22,'Sổ Nhật ký chung'!$D$6:$D$65) -> 708000000 | G22: =SUMIF('Sổ Nhật ký chung'!$C$6:$C$65,'Bang can doi so phat sinh'!C22,'Sổ Nhật ký chung'!$E$6:$E$65) -> 708000000 | H22: 0 | I22: =E22+G22-F22 -> 0
A23: 17 | B23: Giá vốn hàng bán | C23: 632 | D23: 0 | E23: 0 | F23: =SUMIF('Sổ Nhật ký chung'!$C$6:$C$65,'Bang can doi so phat sinh'!C23,'Sổ Nhật ký chung'!$D$6:$D$65) -> 3.6523077e+08 | G23: =SUMIF('Sổ Nhật ký chung'!$C$6:$C$65,'Bang can doi so phat sinh'!C23,'Sổ Nhật ký chung'!$E$6:$E$65) -> 3.6523077e+08 | H23: =D23+F23-G23 -> 0 | I23: =E23+G23-F23 -> 0
A24: 18 | B24: Chi phí tài chính | C24: 635 | D24: 0 | E24: 0 | F24: =SUMIF('Sổ Nhật ký chung'!$C$6:$C$65,'Bang can doi so phat sinh'!C24,'Sổ Nhật ký chung'!$D$6:$D$65) -> 10000000 | G24: =SUMIF('Sổ Nhật ký chung'!$C$6:$C$65,'Bang can doi so phat sinh'!C24,'Sổ Nhật ký chung'!$E$6:$E$65) -> 10000000 | H24: =D24+F24-G24 -> 0 | I24: =E24+G24-F24 -> 0
A25: 19 | B25: Chi phí bán hàng | C25: 641 | D25: 0 | E25: 0 | F25: =SUMIF('Sổ Nhật ký chung'!$C$6:$C$65,'Bang can doi so phat sinh'!C25,'Sổ Nhật ký chung'!$D$6:$D$65) -> 60000000 | G25: =SUMIF('Sổ Nhật ký chung'!$C$6:$C$65,'Bang can doi so phat sinh'!C25,'Sổ Nhật ký chung'!$E$6:$E$65) -> 60000000 | H25: =D25+F25-G25 -> 0 | I25: =E25+G25-F25 -> 0
A26: 20 | B26: Chi phí quản lý doanh nghiệp | C26: 642 | D26: 0 | E26: 0 | F26: =SUMIF('Sổ Nhật ký chung'!$C$6:$C$65,'Bang can doi so phat sinh'!C26,'Sổ Nhật ký chung'!$D$6:$D$65) -> 34425000 | G26: =SUMIF('Sổ Nhật ký chung'!$C$6:$C$65,'Bang can doi so phat sinh'!C26,'Sổ Nhật ký chung'!$E$6:$E$65) -> 34425000 | H26: =D26+F26-G26 -> 0 | I26: =E26+G26-F26 -> 0
A27: 21 | B27: Xác định kết quả kinh doanh | C27: 911 | D27: 0 | E27: 0 | F27: =SUMIF('Sổ Nhật ký chung'!$C$6:$C$65,'Bang can doi so phat sinh'!C27,'Sổ Nhật ký chung'!$D$6:$D$65) -> 708000000 | G27: =SUMIF('Sổ Nhật ký chung'!$C$6:$C$65,'Bang can doi so phat sinh'!C27,'Sổ Nhật ký chung'!$E$6:$E$65) -> 708000000 | H27: =D27+F27-G27 -> 0 | I27: =E27+G27-F27 -> 0
B29: TỔNG CỘNG | F29: =SUM(F5:F28) -> 1.0675456e+10 | G29: =SUM(G5:G28) -> 1.0675456e+10 | H29: =SUM(H5:H28) -> 7.6015692e+09 | I29: =SUM(I5:I28) -> 7.6015692e+09

Sheet Bao cao tai chinh
A1: CÔNG TY CỔ PHẦN FAABULOUS
A2: BẢNG CÂN ĐỐI KẾ TOÁN
A3: Tại ngày 31 tháng 01 năm 20X6
C4: ĐVT: Đồng
A5: TÀI SẢN | C5: NGUỒN VỐN
A6: I. TSNH | B6: =SUM(B7:B12) -> #N/A | C6: III, NỢ PHẢI TRẢ | D6: =SUM(D7:D12) -> 2362800000
A7: Tiền mặt | B7: =VLOOKUP(A7,'Bang can doi so phat sinh'!$B$7:$I$28,7,FALSE) -> 300000000 | C7: Phải trả người bán | D7: =VLOOKUP(C7,'Bang can doi so phat sinh'!$B$7:$I$28,8,FALSE) -> 264000000
A8: Tiền gửi ngân hàng | B8: =VLOOKUP(A8,'Bang can doi so phat sinh'!$B$7:$I$28,7,FALSE) -> 6768000000 | C8: Thuế GTGT phải nộp | D8: =VLOOKUP(C8,'Bang can doi so phat sinh'!$B$7:$I$28,8,FALSE) -> 14800000
A9: Phải thu khách hàng | B9: =VLOOKUP(A9,'Bang can doi so phat sinh'!$B$7:$I$28,7,FALSE) -> 316800000 | C9: Phải trả công nhân viên | D9: =VLOOKUP(C9,'Bang can doi so phat sinh'!$B$7:$I$28,8,FALSE) -> 63000000
A10: Thuế GTGT được khấu trừ | B10: =VLOOKUP(A10,'Bang can doi so phat sinh'!$B$7:$I$28,7,FALSE) -> 0
A11: Hàng hóa | B11: =VLOOKUP(A11,'Bang can doi so phat sinh'!$B$7:$I$28,7,FALSE) -> 94769231 | C11: Các khoản phải trả khác | D11: =VLOOKUP(C11,'Bang can doi so phat sinh'!$B$7:$I$28,8,FALSE) -> 21000000
A12: Chi phí trả trước | B12: =VLOOKUP(A12,'Bang can doi so phat sinh'!$B$7:$I$28,7,FALSE) -> #N/A | C12: Vay | D12: =VLOOKUP(C12,'Bang can doi so phat sinh'!$B$7:$I$28,8,FALSE) -> 2000000000
A13: II. TSDH | B13: =SUM(B14:B15) -> 101575000 | C13: IV. VỐN CHỦ SỞ HỮU | D13: =D14+D15 -> 5.2383442e+09
A14: TSCĐ hữu hình | B14: =VLOOKUP(A14,'Bang can doi so phat sinh'!$B$7:$I$28,7,FALSE) -> 102000000 | C14: vốn đầu tư của chủ sở hữu | D14: =VLOOKUP(C14,'Bang can doi so phat sinh'!$B$7:$I$28,8,FALSE) -> 5000000000
A15: Hao mòn TSCĐ | B15: =-VLOOKUP(A15,'Bang can doi so phat sinh'!$B$7:$I$28,8,FALSE) -> -425000 | C15: Lợi nhuận chưa phân phối | D15: =VLOOKUP(C15,'Bang can doi so phat sinh'!$B$7:$I$28,8,FALSE) -> 2.3834423e+08
A16: TỔNG TÀI SẢN | B16: =B6+B13 -> #N/A | C16: TỔNG NGUỒN VỐN | D16: =D6+D13 -> 7.6011442e+09
A21: CÔNG TY CỔ PHẦN FAABULOUS
A22: BÁO CÁO KẾT QUẢ HOẠT ĐỘNG KINH DOANH
A23: Tháng 1 năm 20X6
C24: ĐVT: triệu đồng
A25: 1. Doanh thu bán hàng và cung cấp dịch vụ | C25: ='Bang can doi so phat sinh'!G22 -> 708000000
A26: 2. Các khoản giảm trừ doanh thu | C26: 0
A27: 3. Doanh thu thuần | C27: =C25-C26 -> 708000000
A28: 4. Giá vốn hàng bán | C28: ='Bang can doi so phat sinh'!F23 -> 3.6523077e+08
A29: 5. Lợi nhuận gộp từ bán hàng và cung cấp dịch vụ | C29: =C27-C28 -> 3.4276923e+08
A30: 6. Doanh thu hoạt động tài chính | C30: 0
A31: 7. Chi phí tài chính | C31: ='Bang can doi so phat sinh'!F24 -> 10000000
A32: 8. Chi phí bán hàng | C32: ='Bang can doi so phat sinh'!F25 -> 60000000
A33: 9. Chi phí quản lý doanh nghiệp | C33: ='Bang can doi so phat sinh'!F26 -> 34425000
A34: 10. Lợi nhuận thuần từ hoạt động kinh doanh | C34: =C29+C30-C31-C32-C33 -> 2.3834423e+08
A35: 11. Thu nhập khác | C35: 0
A36: 12. Chi phí khác | C36: 0
A37: 13. Lợi nhuận trước thuế | C37: =C34+C35-C36 -> 2.3834423e+08
A38: 14. Chi phí thuế TNDN | C38: 0
A39: 15. Lợi nhuận sau thuế | C39: =C37-C38 -> 2.3834423e+08
A44: CÔNG TY TNHH HOÀNG MAI
A45: BÁO CÁO LƯU CHUYỂN TIỀN TỆ (Theo phương pháp trực tiếp)
A46: Tháng 1 năm 2020
C47: ĐVT: triệu đồng
A48: I. Lưu chuyển tiền từ hoạt động kinh doanh
...
